Workbook

Sheet Start
A1: Personal Finance Tracker — Synthetic Demo | B1: Personal Finance Tracker V1 | C1: Personal Finance Tracker V1 | D1: Personal Finance Tracker V1 | E1: Personal Finance Tracker V1 | F1: Personal Finance Tracker V1 | G1: Personal Finance Tracker V1 | H1: Personal Finance Tracker V1
A2: Personal Finance Tracker V1 | B2: Personal Finance Tracker V1 | C2: Personal Finance Tracker V1 | D2: Personal Finance Tracker V1 | E2: Personal Finance Tracker V1 | F2: Personal Finance Tracker V1 | G2: Personal Finance Tracker V1 | H2: Personal Finance Tracker V1
A3: Excel is the source of truth. Record each movement once, then refresh Power BI for analysis. | B3: Excel is the source of truth. Record each movement once, then refresh Power BI for analysis. | C3: Excel is the source of truth. Record each movement once, then refresh Power BI for analysis. | D3: Excel is the source of truth. Record each movement once, then refresh Power BI for analysis. | E3: Excel is the source of truth. Record each movement once, then refresh Power BI for analysis. | F3: Excel is the source of truth. Record each movement once, then refresh Power BI for analysis. | G3: Excel is the source of truth. Record each movement once, then refresh Power BI for analysis. | H3: Excel is the source of truth. Record each movement once, then refresh Power BI for analysis.
A5: Version | B5: V1.0 | C5: Tracking Starts | D5: 46266 | E5: Currency | F5: VND | G5: Entry Goal | H5: < 20 seconds
A7: Setup Checklist | B7: Setup Checklist | C7: Setup Checklist | D7: Setup Checklist | E7: Setup Checklist | F7: Setup Checklist | G7: Setup Checklist | H7: Setup Checklist
A8: 1 | B8: Accounts | C8: Enter each opening balance as of the start of 01/09/2026.
A9: 2 | B9: Liabilities | C9: Enter positive debt owed for tracked credit accounts.
A10: 3 | B10: Categories | C10: Review the default Need/Want and Fixed/Variable classifications.
A11: 4 | B11: Monthly Plan | C11: Set separate expense budgets and Savings & Investment targets.
A13: Daily Entry Rules | B13: Daily Entry Rules | C13: Daily Entry Rules | D13: Daily Entry Rules | E13: Daily Entry Rules | F13: Daily Entry Rules | G13: Daily Entry Rules | H13: Daily Entry Rules
A14: Type | B14: From Account | C14: To Account | D14: Category | E14: Income KPI | F14: Expense KPI | G14: Balance Effect | H14: Typical Use
A15: Income | B15: — | C15: Asset | D15: Income | E15: Yes | F15: No | G15: Asset increases | H15: Salary received
A16: Expense | B16: Asset/Liability | C16: — | D16: Expense | E16: No | F16: Yes | G16: Asset falls or debt rises | H16: Purchase or fee
A17: Refund | B17: — | C17: Asset/Liability | D17: Original expense | E17: No | F17: Reduces | G17: Asset rises or debt falls | H17: Merchant refund
A18: Transfer | B18: Tracked account | C18: Tracked account | D18: Blank | E18: No | F18: No | G18: Moves natural balances | H18: Bank / Wallet transfer or debt payment
A19: Allocation | B19: Asset | C19: — | D19: Savings & Investment | E19: No | F19: No | G19: Tracked cash falls | H19: Money sent to an untracked savings account
A20: Adjustment | B20: One side only | C20: One side only | D20: Blank | E20: No | F20: No | G20: Corrects one balance | H20: Resync an account
A22: Examples | B22: Examples | C22: Examples | D22: Examples | E22: Examples | F22: Examples | G22: Examples | H22: Examples
A23: Scenario | B23: Type | C23: Amount | D23: From | E23: To | F23: Category | G23: Expense? | H23: Notes
A24: Salary to Bank | B24: Income | C24: 3000000 | D24: — | E24: Bank | F24: Salary | G24: No | H24: Increases Bank and Income
A25: Groceries from Bank | B25: Expense | C25: 500000 | D25: Bank | E25: — | F25: Groceries & Essentials | G25: Yes | H25: Reduces Bank
A26: Credit-card purchase | B26: Expense | C26: 200000 | D26: Credit Card | E26: — | F26: Shopping | G26: Yes | H26: Increases debt
A27: Pay credit card | B27: Transfer | C27: 100000 | D27: Bank | E27: Credit Card | F27: — | G27: No | H27: Reduces Bank and debt
A28: Borrow to Bank | B28: Transfer | C28: 30000 | D28: Credit Card | E28: Bank | F28: — | G28: No | H28: Increases Bank and debt
A29: Allocation contribution | B29: Allocation | C29: 400000 | D29: Bank | E29: — | F29: Savings & Investment | G29: No | H29: Counts toward target
A31: Model Convention | B31: Model Convention | C31: Model Convention | D31: Model Convention | E31: Model Convention | F31: Model Convention | G31: Model Convention | H31: Model Convention
A32: Asset balance | B32: Opening Balance + To movements − From movements
A33: Liability balance | B33: Opening Debt + From movements − To movements
A34: Important | B34: Monthly Surplus is Income − Net Expense before Allocation; it is not a bank-balance reconciliation.
A36: Legend | B36: Blue font = editable input | D36: Green font = formula / linked result | G36: Yellow fill = setup needed

Sheet Transactions
A1: Transactions | B1: Transactions | C1: Transactions | D1: Transactions | E1: Transactions | F1: Transactions | G1: Transactions | H1: Transactions | I1: Transactions
A2: All demo transactions are synthetic. Enter positive amounts; Entry Status must show OK. | B2: Enter each real-world movement once. Entry Status flags only core rule conflicts. | C2: Enter each real-world movement once. Entry Status flags only core rule conflicts. | D2: Enter each real-world movement once. Entry Status flags only core rule conflicts. | E2: Enter each real-world movement once. Entry Status flags only core rule conflicts. | F2: Enter each real-world movement once. Entry Status flags only core rule conflicts. | G2: Enter each real-world movement once. Entry Status flags only core rule conflicts. | H2: Enter each real-world movement once. Entry Status flags only core rule conflicts. | I2: Enter each real-world movement once. Entry Status flags only core rule conflicts.
A4: Date | B4: Type | C4: Amount | D4: From Account | E4: To Account | F4: Category | G4: Merchant | H4: Note | I4: Entry Status
A5: 46266 | B5: Income | C5: 3000000 | E5: Bank | F5: Salary | G5: Demo Employer | H5: Synthetic salary | I5: =IF(COUNTA(A5:H5)=0,"",IF(OR(A5="",B5="",C5="",C5<=0),"CHECK: Date, Type and positive Amount required",IF(OR(AND(B5="Income",D5="",E5<>"",F5<>"",COUNTIFS(Accounts!$A$5:$A$50,E5,Accounts!$D$5:$D$50,"Asset")=1,COUNTIFS(Categories!$A$5:$A$100,F5,Categories!$C$5:$C$100,"Income")=1),AND(B5="Expense",D5<>"",E5="",F5<>"",COUNTIF(Accounts!$A$5:$A$50,D5)=1,COUNTIFS(Categories!$A$5:$A$100,F5,Categories!$C$5:$C$100,"Expense")=1),AND(B5="Refund",D5="",E5<>"",F5<>"",COUNTIF(Accounts!$A$5:$A$50,E5)=1,COUNTIFS(Categories!$A$5:$A$100,F5,Categories!$C$5:$C$100,"Expense")=1),AND(B5="Transfer",D5<>"",E5<>"",D5<>E5,F5="",COUNTIF(Accounts!$A$5:$A$50,D5)=1,COUNTIF(Accounts!$A$5:$A$50,E5)=1),AND(B5="Allocation",F5="Savings & Investment",OR(AND(D5<>"",E5="",COUNTIFS(Accounts!$A$5:$A$50,D5,Accounts!$D$5:$D$50,"Asset")=1),AND(D5="",E5<>"",COUNTIFS(Accounts!$A$5:$A$50,E5,Accounts!$D$5:$D$50,"Asset")=1))),AND(B5="Adjustment",F5="",OR(AND(D5<>"",E5="",COUNTIF(Accounts!$A$5:$A$50,D5)=1),AND(D5="",E5<>"",COUNTIF(Accounts!$A$5:$A$50,E5)=1)))),"OK","CHECK: Type / account / category combination"))) -> OK
A6: 46267 | B6: Expense | C6: 500000 | D6: Bank | F6: Groceries & Essentials | G6: Demo Market | H6: Synthetic groceries | I6: =IF(COUNTA(A6:H6)=0,"",IF(OR(A6="",B6="",C6="",C6<=0),"CHECK: Date, Type and positive Amount required",IF(OR(AND(B6="Income",D6="",E6<>"",F6<>"",COUNTIFS(Accounts!$A$5:$A$50,E6,Accounts!$D$5:$D$50,"Asset")=1,COUNTIFS(Categories!$A$5:$A$100,F6,Categories!$C$5:$C$100,"Income")=1),AND(B6="Expense",D6<>"",E6="",F6<>"",COUNTIF(Accounts!$A$5:$A$50,D6)=1,COUNTIFS(Categories!$A$5:$A$100,F6,Categories!$C$5:$C$100,"Expense")=1),AND(B6="Refund",D6="",E6<>"",F6<>"",COUNTIF(Accounts!$A$5:$A$50,E6)=1,COUNTIFS(Categories!$A$5:$A$100,F6,Categories!$C$5:$C$100,"Expense")=1),AND(B6="Transfer",D6<>"",E6<>"",D6<>E6,F6="",COUNTIF(Accounts!$A$5:$A$50,D6)=1,COUNTIF(Accounts!$A$5:$A$50,E6)=1),AND(B6="Allocation",F6="Savings & Investment",OR(AND(D6<>"",E6="",COUNTIFS(Accounts!$A$5:$A$50,D6,Accounts!$D$5:$D$50,"Asset")=1),AND(D6="",E6<>"",COUNTIFS(Accounts!$A$5:$A$50,E6,Accounts!$D$5:$D$50,"Asset")=1))),AND(B6="Adjustment",F6="",OR(AND(D6<>"",E6="",COUNTIF(Accounts!$A$5:$A$50,D6)=1),AND(D6="",E6<>"",COUNTIF(Accounts!$A$5:$A$50,E6)=1)))),"OK","CHECK: Type / account / category combination"))) -> OK
A7: 46268 | B7: Expense | C7: 200000 | D7: Credit Card | F7: Shopping | G7: Demo Shop | H7: Synthetic credit purchase | I7: =IF(COUNTA(A7:H7)=0,"",IF(OR(A7="",B7="",C7="",C7<=0),"CHECK: Date, Type and positive Amount required",IF(OR(AND(B7="Income",D7="",E7<>"",F7<>"",COUNTIFS(Accounts!$A$5:$A$50,E7,Accounts!$D$5:$D$50,"Asset")=1,COUNTIFS(Categories!$A$5:$A$100,F7,Categories!$C$5:$C$100,"Income")=1),AND(B7="Expense",D7<>"",E7="",F7<>"",COUNTIF(Accounts!$A$5:$A$50,D7)=1,COUNTIFS(Categories!$A$5:$A$100,F7,Categories!$C$5:$C$100,"Expense")=1),AND(B7="Refund",D7="",E7<>"",F7<>"",COUNTIF(Accounts!$A$5:$A$50,E7)=1,COUNTIFS(Categories!$A$5:$A$100,F7,Categories!$C$5:$C$100,"Expense")=1),AND(B7="Transfer",D7<>"",E7<>"",D7<>E7,F7="",COUNTIF(Accounts!$A$5:$A$50,D7)=1,COUNTIF(Accounts!$A$5:$A$50,E7)=1),AND(B7="Allocation",F7="Savings & Investment",OR(AND(D7<>"",E7="",COUNTIFS(Accounts!$A$5:$A$50,D7,Accounts!$D$5:$D$50,"Asset")=1),AND(D7="",E7<>"",COUNTIFS(Accounts!$A$5:$A$50,E7,Accounts!$D$5:$D$50,"Asset")=1))),AND(B7="Adjustment",F7="",OR(AND(D7<>"",E7="",COUNTIF(Accounts!$A$5:$A$50,D7)=1),AND(D7="",E7<>"",COUNTIF(Accounts!$A$5:$A$50,E7)=1)))),"OK","CHECK: Type / account / category combination"))) -> OK
A8: 46269 | B8: Transfer | C8: 100000 | D8: Bank | E8: Credit Card | H8: Synthetic card repayment | I8: =IF(COUNTA(A8:H8)=0,"",IF(OR(A8="",B8="",C8="",C8<=0),"CHECK: Date, Type and positive Amount required",IF(OR(AND(B8="Income",D8="",E8<>"",F8<>"",COUNTIFS(Accounts!$A$5:$A$50,E8,Accounts!$D$5:$D$50,"Asset")=1,COUNTIFS(Categories!$A$5:$A$100,F8,Categories!$C$5:$C$100,"Income")=1),AND(B8="Expense",D8<>"",E8="",F8<>"",COUNTIF(Accounts!$A$5:$A$50,D8)=1,COUNTIFS(Categories!$A$5:$A$100,F8,Categories!$C$5:$C$100,"Expense")=1),AND(B8="Refund",D8="",E8<>"",F8<>"",COUNTIF(Accounts!$A$5:$A$50,E8)=1,COUNTIFS(Categories!$A$5:$A$100,F8,Categories!$C$5:$C$100,"Expense")=1),AND(B8="Transfer",D8<>"",E8<>"",D8<>E8,F8="",COUNTIF(Accounts!$A$5:$A$50,D8)=1,COUNTIF(Accounts!$A$5:$A$50,E8)=1),AND(B8="Allocation",F8="Savings & Investment",OR(AND(D8<>"",E8="",COUNTIFS(Accounts!$A$5:$A$50,D8,Accounts!$D$5:$D$50,"Asset")=1),AND(D8="",E8<>"",COUNTIFS(Accounts!$A$5:$A$50,E8,Accounts!$D$5:$D$50,"Asset")=1))),AND(B8="Adjustment",F8="",OR(AND(D8<>"",E8="",COUNTIF(Accounts!$A$5:$A$50,D8)=1),AND(D8="",E8<>"",COUNTIF(Accounts!$A$5:$A$50,E8)=1)))),"OK","CHECK: Type / account / category combination"))) -> OK
A9: 46270 | B9: Transfer | C9: 50000 | D9: Bank | E9: Wallet | H9: Synthetic wallet funding | I9: =IF(COUNTA(A9:H9)=0,"",IF(OR(A9="",B9="",C9="",C9<=0),"CHECK: Date, Type and positive Amount required",IF(OR(AND(B9="Income",D9="",E9<>"",F9<>"",COUNTIFS(Accounts!$A$5:$A$50,E9,Accounts!$D$5:$D$50,"Asset")=1,COUNTIFS(Categories!$A$5:$A$100,F9,Categories!$C$5:$C$100,"Income")=1),AND(B9="Expense",D9<>"",E9="",F9<>"",COUNTIF(Accounts!$A$5:$A$50,D9)=1,COUNTIFS(Categories!$A$5:$A$100,F9,Categories!$C$5:$C$100,"Expense")=1),AND(B9="Refund",D9="",E9<>"",F9<>"",COUNTIF(Accounts!$A$5:$A$50,E9)=1,COUNTIFS(Categories!$A$5:$A$100,F9,Categories!$C$5:$C$100,"Expense")=1),AND(B9="Transfer",D9<>"",E9<>"",D9<>E9,F9="",COUNTIF(Accounts!$A$5:$A$50,D9)=1,COUNTIF(Accounts!$A$5:$A$50,E9)=1),AND(B9="Allocation",F9="Savings & Investment",OR(AND(D9<>"",E9="",COUNTIFS(Accounts!$A$5:$A$50,D9,Accounts!$D$5:$D$50,"Asset")=1),AND(D9="",E9<>"",COUNTIFS(Accounts!$A$5:$A$50,E9,Accounts!$D$5:$D$50,"Asset")=1))),AND(B9="Adjustment",F9="",OR(AND(D9<>"",E9="",COUNTIF(Accounts!$A$5:$A$50,D9)=1),AND(D9="",E9<>"",COUNTIF(Accounts!$A$5:$A$50,E9)=1)))),"OK","CHECK: Type / account / category combination"))) -> OK
A10: 46271 | B10: Refund | C10: 20000 | E10: Credit Card | F10: Shopping | G10: Demo Shop | H10: Synthetic card refund | I10: =IF(COUNTA(A10:H10)=0,"",IF(OR(A10="",B10="",C10="",C10<=0),"CHECK: Date, Type and positive Amount required",IF(OR(AND(B10="Income",D10="",E10<>"",F10<>"",COUNTIFS(Accounts!$A$5:$A$50,E10,Accounts!$D$5:$D$50,"Asset")=1,COUNTIFS(Categories!$A$5:$A$100,F10,Categories!$C$5:$C$100,"Income")=1),AND(B10="Expense",D10<>"",E10="",F10<>"",COUNTIF(Accounts!$A$5:$A$50,D10)=1,COUNTIFS(Categories!$A$5:$A$100,F10,Categories!$C$5:$C$100,"Expense")=1),AND(B10="Refund",D10="",E10<>"",F10<>"",COUNTIF(Accounts!$A$5:$A$50,E10)=1,COUNTIFS(Categories!$A$5:$A$100,F10,Categories!$C$5:$C$100,"Expense")=1),AND(B10="Transfer",D10<>"",E10<>"",D10<>E10,F10="",COUNTIF(Accounts!$A$5:$A$50,D10)=1,COUNTIF(Accounts!$A$5:$A$50,E10)=1),AND(B10="Allocation",F10="Savings & Investment",OR(AND(D10<>"",E10="",COUNTIFS(Accounts!$A$5:$A$50,D10,Accounts!$D$5:$D$50,"Asset")=1),AND(D10="",E10<>"",COUNTIFS(Accounts!$A$5:$A$50,E10,Accounts!$D$5:$D$50,"Asset")=1))),AND(B10="Adjustment",F10="",OR(AND(D10<>"",E10="",COUNTIF(Accounts!$A$5:$A$50,D10)=1),AND(D10="",E10<>"",COUNTIF(Accounts!$A$5:$A$50,E10)=1)))),"OK","CHECK: Type / account / category combination"))) -> OK
A11: 46272 | B11: Allocation | C11: 400000 | D11: Bank | F11: Savings & Investment | H11: Synthetic allocation contribution | I11: =IF(COUNTA(A11:H11)=0,"",IF(OR(A11="",B11="",C11="",C11<=0),"CHECK: Date, Type and positive Amount required",IF(OR(AND(B11="Income",D11="",E11<>"",F11<>"",COUNTIFS(Accounts!$A$5:$A$50,E11,Accounts!$D$5:$D$50,"Asset")=1,COUNTIFS(Categories!$A$5:$A$100,F11,Categories!$C$5:$C$100,"Income")=1),AND(B11="Expense",D11<>"",E11="",F11<>"",COUNTIF(Accounts!$A$5:$A$50,D11)=1,COUNTIFS(Categories!$A$5:$A$100,F11,Categories!$C$5:$C$100,"Expense")=1),AND(B11="Refund",D11="",E11<>"",F11<>"",COUNTIF(Accounts!$A$5:$A$50,E11)=1,COUNTIFS(Categories!$A$5:$A$100,F11,Categories!$C$5:$C$100,"Expense")=1),AND(B11="Transfer",D11<>"",E11<>"",D11<>E11,F11="",COUNTIF(Accounts!$A$5:$A$50,D11)=1,COUNTIF(Accounts!$A$5:$A$50,E11)=1),AND(B11="Allocation",F11="Savings & Investment",OR(AND(D11<>"",E11="",COUNTIFS(Accounts!$A$5:$A$50,D11,Accounts!$D$5:$D$50,"Asset")=1),AND(D11="",E11<>"",COUNTIFS(Accounts!$A$5:$A$50,E11,Accounts!$D$5:$D$50,"Asset")=1))),AND(B11="Adjustment",F11="",OR(AND(D11<>"",E11="",COUNTIF(Accounts!$A$5:$A$50,D11)=1),AND(D11="",E11<>"",COUNTIF(Accounts!$A$5:$A$50,E11)=1)))),"OK","CHECK: Type / account / category combination"))) -> OK
A12: 46273 | B12: Allocation | C12: 100000 | E12: Bank | F12: Savings & Investment | H12: Synthetic allocation return | I12: =IF(COUNTA(A12:H12)=0,"",IF(OR(A12="",B12="",C12="",C12<=0),"CHECK: Date, Type and positive Amount required",IF(OR(AND(B12="Income",D12="",E12<>"",F12<>"",COUNTIFS(Accounts!$A$5:$A$50,E12,Accounts!$D$5:$D$50,"Asset")=1,COUNTIFS(Categories!$A$5:$A$100,F12,Categories!$C$5:$C$100,"Income")=1),AND(B12="Expense",D12<>"",E12="",F12<>"",COUNTIF(Accounts!$A$5:$A$50,D12)=1,COUNTIFS(Categories!$A$5:$A$100,F12,Categories!$C$5:$C$100,"Expense")=1),AND(B12="Refund",D12="",E12<>"",F12<>"",COUNTIF(Accounts!$A$5:$A$50,E12)=1,COUNTIFS(Categories!$A$5:$A$100,F12,Categories!$C$5:$C$100,"Expense")=1),AND(B12="Transfer",D12<>"",E12<>"",D12<>E12,F12="",COUNTIF(Accounts!$A$5:$A$50,D12)=1,COUNTIF(Accounts!$A$5:$A$50,E12)=1),AND(B12="Allocation",F12="Savings & Investment",OR(AND(D12<>"",E12="",COUNTIFS(Accounts!$A$5:$A$50,D12,Accounts!$D$5:$D$50,"Asset")=1),AND(D12="",E12<>"",COUNTIFS(Accounts!$A$5:$A$50,E12,Accounts!$D$5:$D$50,"Asset")=1))),AND(B12="Adjustment",F12="",OR(AND(D12<>"",E12="",COUNTIF(Accounts!$A$5:$A$50,D12)=1),AND(D12="",E12<>"",COUNTIF(Accounts!$A$5:$A$50,E12)=1)))),"OK","CHECK: Type / account / category combination"))) -> OK
A13: 46274 | B13: Transfer | C13: 30000 | D13: Credit Card | E13: Bank | H13: Synthetic borrowing | I13: =IF(COUNTA(A13:H13)=0,"",IF(OR(A13="",B13="",C13="",C13<=0),"CHECK: Date, Type and positive Amount required",IF(OR(AND(B13="Income",D13="",E13<>"",F13<>"",COUNTIFS(Accounts!$A$5:$A$50,E13,Accounts!$D$5:$D$50,"Asset")=1,COUNTIFS(Categories!$A$5:$A$100,F13,Categories!$C$5:$C$100,"Income")=1),AND(B13="Expense",D13<>"",E13="",F13<>"",COUNTIF(Accounts!$A$5:$A$50,D13)=1,COUNTIFS(Categories!$A$5:$A$100,F13,Categories!$C$5:$C$100,"Expense")=1),AND(B13="Refund",D13="",E13<>"",F13<>"",COUNTIF(Accounts!$A$5:$A$50,E13)=1,COUNTIFS(Categories!$A$5:$A$100,F13,Categories!$C$5:$C$100,"Expense")=1),AND(B13="Transfer",D13<>"",E13<>"",D13<>E13,F13="",COUNTIF(Accounts!$A$5:$A$50,D13)=1,COUNTIF(Accounts!$A$5:$A$50,E13)=1),AND(B13="Allocation",F13="Savings & Investment",OR(AND(D13<>"",E13="",COUNTIFS(Accounts!$A$5:$A$50,D13,Accounts!$D$5:$D$50,"Asset")=1),AND(D13="",E13<>"",COUNTIFS(Accounts!$A$5:$A$50,E13,Accounts!$D$5:$D$50,"Asset")=1))),AND(B13="Adjustment",F13="",OR(AND(D13<>"",E13="",COUNTIF(Accounts!$A$5:$A$50,D13)=1),AND(D13="",E13<>"",COUNTIF(Accounts!$A$5:$A$50,E13)=1)))),"OK","CHECK: Type / account / category combination"))) -> OK
A14: 46275 | B14: Expense | C14: 10000 | D14: Credit Card | F14: Fees & Interest | G14: Demo Bank | H14: Synthetic card fee | I14: =IF(COUNTA(A14:H14)=0,"",IF(OR(A14="",B14="",C14="",C14<=0),"CHECK: Date, Type and positive Amount required",IF(OR(AND(B14="Income",D14="",E14<>"",F14<>"",COUNTIFS(Accounts!$A$5:$A$50,E14,Accounts!$D$5:$D$50,"Asset")=1,COUNTIFS(Categories!$A$5:$A$100,F14,Categories!$C$5:$C$100,"Income")=1),AND(B14="Expense",D14<>"",E14="",F14<>"",COUNTIF(Accounts!$A$5:$A$50,D14)=1,COUNTIFS(Categories!$A$5:$A$100,F14,Categories!$C$5:$C$100,"Expense")=1),AND(B14="Refund",D14="",E14<>"",F14<>"",COUNTIF(Accounts!$A$5:$A$50,E14)=1,COUNTIFS(Categories!$A$5:$A$100,F14,Categories!$C$5:$C$100,"Expense")=1),AND(B14="Transfer",D14<>"",E14<>"",D14<>E14,F14="",COUNTIF(Accounts!$A$5:$A$50,D14)=1,COUNTIF(Accounts!$A$5:$A$50,E14)=1),AND(B14="Allocation",F14="Savings & Investment",OR(AND(D14<>"",E14="",COUNTIFS(Accounts!$A$5:$A$50,D14,Accounts!$D$5:$D$50,"Asset")=1),AND(D14="",E14<>"",COUNTIFS(Accounts!$A$5:$A$50,E14,Accounts!$D$5:$D$50,"Asset")=1))),AND(B14="Adjustment",F14="",OR(AND(D14<>"",E14="",COUNTIF(Accounts!$A$5:$A$50,D14)=1),AND(D14="",E14<>"",COUNTIF(Accounts!$A$5:$A$50,E14)=1)))),"OK","CHECK: Type / account / category combination"))) -> OK
A15: 46276 | B15: Refund | C15: 50000 | E15: Bank | F15: Groceries & Essentials | G15: Demo Market | H15: Synthetic bank refund | I15: =IF(COUNTA(A15:H15)=0,"",IF(OR(A15="",B15="",C15="",C15<=0),"CHECK: Date, Type and positive Amount required",IF(OR(AND(B15="Income",D15="",E15<>"",F15<>"",COUNTIFS(Accounts!$A$5:$A$50,E15,Accounts!$D$5:$D$50,"Asset")=1,COUNTIFS(Categories!$A$5:$A$100,F15,Categories!$C$5:$C$100,"Income")=1),AND(B15="Expense",D15<>"",E15="",F15<>"",COUNTIF(Accounts!$A$5:$A$50,D15)=1,COUNTIFS(Categories!$A$5:$A$100,F15,Categories!$C$5:$C$100,"Expense")=1),AND(B15="Refund",D15="",E15<>"",F15<>"",COUNTIF(Accounts!$A$5:$A$50,E15)=1,COUNTIFS(Categories!$A$5:$A$100,F15,Categories!$C$5:$C$100,"Expense")=1),AND(B15="Transfer",D15<>"",E15<>"",D15<>E15,F15="",COUNTIF(Accounts!$A$5:$A$50,D15)=1,COUNTIF(Accounts!$A$5:$A$50,E15)=1),AND(B15="Allocation",F15="Savings & Investment",OR(AND(D15<>"",E15="",COUNTIFS(Accounts!$A$5:$A$50,D15,Accounts!$D$5:$D$50,"Asset")=1),AND(D15="",E15<>"",COUNTIFS(Accounts!$A$5:$A$50,E15,Accounts!$D$5:$D$50,"Asset")=1))),AND(B15="Adjustment",F15="",OR(AND(D15<>"",E15="",COUNTIF(Accounts!$A$5:$A$50,D15)=1),AND(D15="",E15<>"",COUNTIF(Accounts!$A$5:$A$50,E15)=1)))),"OK","CHECK: Type / account / category combination"))) -> OK
A16: 46277 | B16: Adjustment | C16: 5000 | E16: Wallet | H16: Synthetic wallet adjustment | I16: =IF(COUNTA(A16:H16)=0,"",IF(OR(A16="",B16="",C16="",C16<=0),"CHECK: Date, Type and positive Amount required",IF(OR(AND(B16="Income",D16="",E16<>"",F16<>"",COUNTIFS(Accounts!$A$5:$A$50,E16,Accounts!$D$5:$D$50,"Asset")=1,COUNTIFS(Categories!$A$5:$A$100,F16,Categories!$C$5:$C$100,"Income")=1),AND(B16="Expense",D16<>"",E16="",F16<>"",COUNTIF(Accounts!$A$5:$A$50,D16)=1,COUNTIFS(Categories!$A$5:$A$100,F16,Categories!$C$5:$C$100,"Expense")=1),AND(B16="Refund",D16="",E16<>"",F16<>"",COUNTIF(Accounts!$A$5:$A$50,E16)=1,COUNTIFS(Categories!$A$5:$A$100,F16,Categories!$C$5:$C$100,"Expense")=1),AND(B16="Transfer",D16<>"",E16<>"",D16<>E16,F16="",COUNTIF(Accounts!$A$5:$A$50,D16)=1,COUNTIF(Accounts!$A$5:$A$50,E16)=1),AND(B16="Allocation",F16="Savings & Investment",OR(AND(D16<>"",E16="",COUNTIFS(Accounts!$A$5:$A$50,D16,Accounts!$D$5:$D$50,"Asset")=1),AND(D16="",E16<>"",COUNTIFS(Accounts!$A$5:$A$50,E16,Accounts!$D$5:$D$50,"Asset")=1))),AND(B16="Adjustment",F16="",OR(AND(D16<>"",E16="",COUNTIF(Accounts!$A$5:$A$50,D16)=1),AND(D16="",E16<>"",COUNTIF(Accounts!$A$5:$A$50,E16)=1)))),"OK","CHECK: Type / account / category combination"))) -> OK
I17: =IF(COUNTA(A17:H17)=0,"",IF(OR(A17="",B17="",C17="",C17<=0),"CHECK: Date, Type and positive Amount required",IF(OR(AND(B17="Income",D17="",E17<>"",F17<>"",COUNTIFS(Accounts!$A$5:$A$50,E17,Accounts!$D$5:$D$50,"Asset")=1,COUNTIFS(Categories!$A$5:$A$100,F17,Categories!$C$5:$C$100,"Income")=1),AND(B17="Expense",D17<>"",E17="",F17<>"",COUNTIF(Accounts!$A$5:$A$50,D17)=1,COUNTIFS(Categories!$A$5:$A$100,F17,Categories!$C$5:$C$100,"Expense")=1),AND(B17="Refund",D17="",E17<>"",F17<>"",COUNTIF(Accounts!$A$5:$A$50,E17)=1,COUNTIFS(Categories!$A$5:$A$100,F17,Categories!$C$5:$C$100,"Expense")=1),AND(B17="Transfer",D17<>"",E17<>"",D17<>E17,F17="",COUNTIF(Accounts!$A$5:$A$50,D17)=1,COUNTIF(Accounts!$A$5:$A$50,E17)=1),AND(B17="Allocation",F17="Savings & Investment",OR(AND(D17<>"",E17="",COUNTIFS(Accounts!$A$5:$A$50,D17,Accounts!$D$5:$D$50,"Asset")=1),AND(D17="",E17<>"",COUNTIFS(Accounts!$A$5:$A$50,E17,Accounts!$D$5:$D$50,"Asset")=1))),AND(B17="Adjustment",F17="",OR(AND(D17<>"",E17="",COUNTIF(Accounts!$A$5:$A$50,D17)=1),AND(D17="",E17<>"",COUNTIF(Accounts!$A$5:$A$50,E17)=1)))),"OK","CHECK: Type / account / category combination")))
I18: =IF(COUNTA(A18:H18)=0,"",IF(OR(A18="",B18="",C18="",C18<=0),"CHECK: Date, Type and positive Amount required",IF(OR(AND(B18="Income",D18="",E18<>"",F18<>"",COUNTIFS(Accounts!$A$5:$A$50,E18,Accounts!$D$5:$D$50,"Asset")=1,COUNTIFS(Categories!$A$5:$A$100,F18,Categories!$C$5:$C$100,"Income")=1),AND(B18="Expense",D18<>"",E18="",F18<>"",COUNTIF(Accounts!$A$5:$A$50,D18)=1,COUNTIFS(Categories!$A$5:$A$100,F18,Categories!$C$5:$C$100,"Expense")=1),AND(B18="Refund",D18="",E18<>"",F18<>"",COUNTIF(Accounts!$A$5:$A$50,E18)=1,COUNTIFS(Categories!$A$5:$A$100,F18,Categories!$C$5:$C$100,"Expense")=1),AND(B18="Transfer",D18<>"",E18<>"",D18<>E18,F18="",COUNTIF(Accounts!$A$5:$A$50,D18)=1,COUNTIF(Accounts!$A$5:$A$50,E18)=1),AND(B18="Allocation",F18="Savings & Investment",OR(AND(D18<>"",E18="",COUNTIFS(Accounts!$A$5:$A$50,D18,Accounts!$D$5:$D$50,"Asset")=1),AND(D18="",E18<>"",COUNTIFS(Accounts!$A$5:$A$50,E18,Accounts!$D$5:$D$50,"Asset")=1))),AND(B18="Adjustment",F18="",OR(AND(D18<>"",E18="",COUNTIF(Accounts!$A$5:$A$50,D18)=1),AND(D18="",E18<>"",COUNTIF(Accounts!$A$5:$A$50,E18)=1)))),"OK","CHECK: Type / account / category combination")))
I19: =IF(COUNTA(A19:H19)=0,"",IF(OR(A19="",B19="",C19="",C19<=0),"CHECK: Date, Type and positive Amount required",IF(OR(AND(B19="Income",D19="",E19<>"",F19<>"",COUNTIFS(Accounts!$A$5:$A$50,E19,Accounts!$D$5:$D$50,"Asset")=1,COUNTIFS(Categories!$A$5:$A$100,F19,Categories!$C$5:$C$100,"Income")=1),AND(B19="Expense",D19<>"",E19="",F19<>"",COUNTIF(Accounts!$A$5:$A$50,D19)=1,COUNTIFS(Categories!$A$5:$A$100,F19,Categories!$C$5:$C$100,"Expense")=1),AND(B19="Refund",D19="",E19<>"",F19<>"",COUNTIF(Accounts!$A$5:$A$50,E19)=1,COUNTIFS(Categories!$A$5:$A$100,F19,Categories!$C$5:$C$100,"Expense")=1),AND(B19="Transfer",D19<>"",E19<>"",D19<>E19,F19="",COUNTIF(Accounts!$A$5:$A$50,D19)=1,COUNTIF(Accounts!$A$5:$A$50,E19)=1),AND(B19="Allocation",F19="Savings & Investment",OR(AND(D19<>"",E19="",COUNTIFS(Accounts!$A$5:$A$50,D19,Accounts!$D$5:$D$50,"Asset")=1),AND(D19="",E19<>"",COUNTIFS(Accounts!$A$5:$A$50,E19,Accounts!$D$5:$D$50,"Asset")=1))),AND(B19="Adjustment",F19="",OR(AND(D19<>"",E19="",COUNTIF(Accounts!$A$5:$A$50,D19)=1),AND(D19="",E19<>"",COUNTIF(Accounts!$A$5:$A$50,E19)=1)))),"OK","CHECK: Type / account / category combination")))
I20: =IF(COUNTA(A20:H20)=0,"",IF(OR(A20="",B20="",C20="",C20<=0),"CHECK: Date, Type and positive Amount required",IF(OR(AND(B20="Income",D20="",E20<>"",F20<>"",COUNTIFS(Accounts!$A$5:$A$50,E20,Accounts!$D$5:$D$50,"Asset")=1,COUNTIFS(Categories!$A$5:$A$100,F20,Categories!$C$5:$C$100,"Income")=1),AND(B20="Expense",D20<>"",E20="",F20<>"",COUNTIF(Accounts!$A$5:$A$50,D20)=1,COUNTIFS(Categories!$A$5:$A$100,F20,Categories!$C$5:$C$100,"Expense")=1),AND(B20="Refund",D20="",E20<>"",F20<>"",COUNTIF(Accounts!$A$5:$A$50,E20)=1,COUNTIFS(Categories!$A$5:$A$100,F20,Categories!$C$5:$C$100,"Expense")=1),AND(B20="Transfer",D20<>"",E20<>"",D20<>E20,F20="",COUNTIF(Accounts!$A$5:$A$50,D20)=1,COUNTIF(Accounts!$A$5:$A$50,E20)=1),AND(B20="Allocation",F20="Savings & Investment",OR(AND(D20<>"",E20="",COUNTIFS(Accounts!$A$5:$A$50,D20,Accounts!$D$5:$D$50,"Asset")=1),AND(D20="",E20<>"",COUNTIFS(Accounts!$A$5:$A$50,E20,Accounts!$D$5:$D$50,"Asset")=1))),AND(B20="Adjustment",F20="",OR(AND(D20<>"",E20="",COUNTIF(Accounts!$A$5:$A$50,D20)=1),AND(D20="",E20<>"",COUNTIF(Accounts!$A$5:$A$50,E20)=1)))),"OK","CHECK: Type / account / category combination")))
I21: =IF(COUNTA(A21:H21)=0,"",IF(OR(A21="",B21="",C21="",C21<=0),"CHECK: Date, Type and positive Amount required",IF(OR(AND(B21="Income",D21="",E21<>"",F21<>"",COUNTIFS(Accounts!$A$5:$A$50,E21,Accounts!$D$5:$D$50,"Asset")=1,COUNTIFS(Categories!$A$5:$A$100,F21,Categories!$C$5:$C$100,"Income")=1),AND(B21="Expense",D21<>"",E21="",F21<>"",COUNTIF(Accounts!$A$5:$A$50,D21)=1,COUNTIFS(Categories!$A$5:$A$100,F21,Categories!$C$5:$C$100,"Expense")=1),AND(B21="Refund",D21="",E21<>"",F21<>"",COUNTIF(Accounts!$A$5:$A$50,E21)=1,COUNTIFS(Categories!$A$5:$A$100,F21,Categories!$C$5:$C$100,"Expense")=1),AND(B21="Transfer",D21<>"",E21<>"",D21<>E21,F21="",COUNTIF(Accounts!$A$5:$A$50,D21)=1,COUNTIF(Accounts!$A$5:$A$50,E21)=1),AND(B21="Allocation",F21="Savings & Investment",OR(AND(D21<>"",E21="",COUNTIFS(Accounts!$A$5:$A$50,D21,Accounts!$D$5:$D$50,"Asset")=1),AND(D21="",E21<>"",COUNTIFS(Accounts!$A$5:$A$50,E21,Accounts!$D$5:$D$50,"Asset")=1))),AND(B21="Adjustment",F21="",OR(AND(D21<>"",E21="",COUNTIF(Accounts!$A$5:$A$50,D21)=1),AND(D21="",E21<>"",COUNTIF(Accounts!$A$5:$A$50,E21)=1)))),"OK","CHECK: Type / account / category combination")))
I22: =IF(COUNTA(A22:H22)=0,"",IF(OR(A22="",B22="",C22="",C22<=0),"CHECK: Date, Type and positive Amount required",IF(OR(AND(B22="Income",D22="",E22<>"",F22<>"",COUNTIFS(Accounts!$A$5:$A$50,E22,Accounts!$D$5:$D$50,"Asset")=1,COUNTIFS(Categories!$A$5:$A$100,F22,Categories!$C$5:$C$100,"Income")=1),AND(B22="Expense",D22<>"",E22="",F22<>"",COUNTIF(Accounts!$A$5:$A$50,D22)=1,COUNTIFS(Categories!$A$5:$A$100,F22,Categories!$C$5:$C$100,"Expense")=1),AND(B22="Refund",D22="",E22<>"",F22<>"",COUNTIF(Accounts!$A$5:$A$50,E22)=1,COUNTIFS(Categories!$A$5:$A$100,F22,Categories!$C$5:$C$100,"Expense")=1),AND(B22="Transfer",D22<>"",E22<>"",D22<>E22,F22="",COUNTIF(Accounts!$A$5:$A$50,D22)=1,COUNTIF(Accounts!$A$5:$A$50,E22)=1),AND(B22="Allocation",F22="Savings & Investment",OR(AND(D22<>"",E22="",COUNTIFS(Accounts!$A$5:$A$50,D22,Accounts!$D$5:$D$50,"Asset")=1),AND(D22="",E22<>"",COUNTIFS(Accounts!$A$5:$A$50,E22,Accounts!$D$5:$D$50,"Asset")=1))),AND(B22="Adjustment",F22="",OR(AND(D22<>"",E22="",COUNTIF(Accounts!$A$5:$A$50,D22)=1),AND(D22="",E22<>"",COUNTIF(Accounts!$A$5:$A$50,E22)=1)))),"OK","CHECK: Type / account / category combination")))
I23: =IF(COUNTA(A23:H23)=0,"",IF(OR(A23="",B23="",C23="",C23<=0),"CHECK: Date, Type and positive Amount required",IF(OR(AND(B23="Income",D23="",E23<>"",F23<>"",COUNTIFS(Accounts!$A$5:$A$50,E23,Accounts!$D$5:$D$50,"Asset")=1,COUNTIFS(Categories!$A$5:$A$100,F23,Categories!$C$5:$C$100,"Income")=1),AND(B23="Expense",D23<>"",E23="",F23<>"",COUNTIF(Accounts!$A$5:$A$50,D23)=1,COUNTIFS(Categories!$A$5:$A$100,F23,Categories!$C$5:$C$100,"Expense")=1),AND(B23="Refund",D23="",E23<>"",F23<>"",COUNTIF(Accounts!$A$5:$A$50,E23)=1,COUNTIFS(Categories!$A$5:$A$100,F23,Categories!$C$5:$C$100,"Expense")=1),AND(B23="Transfer",D23<>"",E23<>"",D23<>E23,F23="",COUNTIF(Accounts!$A$5:$A$50,D23)=1,COUNTIF(Accounts!$A$5:$A$50,E23)=1),AND(B23="Allocation",F23="Savings & Investment",OR(AND(D23<>"",E23="",COUNTIFS(Accounts!$A$5:$A$50,D23,Accounts!$D$5:$D$50,"Asset")=1),AND(D23="",E23<>"",COUNTIFS(Accounts!$A$5:$A$50,E23,Accounts!$D$5:$D$50,"Asset")=1))),AND(B23="Adjustment",F23="",OR(AND(D23<>"",E23="",COUNTIF(Accounts!$A$5:$A$50,D23)=1),AND(D23="",E23<>"",COUNTIF(Accounts!$A$5:$A$50,E23)=1)))),"OK","CHECK: Type / account / category combination")))
I24: =IF(COUNTA(A24:H24)=0,"",IF(OR(A24="",B24="",C24="",C24<=0),"CHECK: Date, Type and positive Amount required",IF(OR(AND(B24="Income",D24="",E24<>"",F24<>"",COUNTIFS(Accounts!$A$5:$A$50,E24,Accounts!$D$5:$D$50,"Asset")=1,COUNTIFS(Categories!$A$5:$A$100,F24,Categories!$C$5:$C$100,"Income")=1),AND(B24="Expense",D24<>"",E24="",F24<>"",COUNTIF(Accounts!$A$5:$A$50,D24)=1,COUNTIFS(Categories!$A$5:$A$100,F24,Categories!$C$5:$C$100,"Expense")=1),AND(B24="Refund",D24="",E24<>"",F24<>"",COUNTIF(Accounts!$A$5:$A$50,E24)=1,COUNTIFS(Categories!$A$5:$A$100,F24,Categories!$C$5:$C$100,"Expense")=1),AND(B24="Transfer",D24<>"",E24<>"",D24<>E24,F24="",COUNTIF(Accounts!$A$5:$A$50,D24)=1,COUNTIF(Accounts!$A$5:$A$50,E24)=1),AND(B24="Allocation",F24="Savings & Investment",OR(AND(D24<>"",E24="",COUNTIFS(Accounts!$A$5:$A$50,D24,Accounts!$D$5:$D$50,"Asset")=1),AND(D24="",E24<>"",COUNTIFS(Accounts!$A$5:$A$50,E24,Accounts!$D$5:$D$50,"Asset")=1))),AND(B24="Adjustment",F24="",OR(AND(D24<>"",E24="",COUNTIF(Accounts!$A$5:$A$50,D24)=1),AND(D24="",E24<>"",COUNTIF(Accounts!$A$5:$A$50,E24)=1)))),"OK","CHECK: Type / account / category combination")))
I25: =IF(COUNTA(A25:H25)=0,"",IF(OR(A25="",B25="",C25="",C25<=0),"CHECK: Date, Type and positive Amount required",IF(OR(AND(B25="Income",D25="",E25<>"",F25<>"",COUNTIFS(Accounts!$A$5:$A$50,E25,Accounts!$D$5:$D$50,"Asset")=1,COUNTIFS(Categories!$A$5:$A$100,F25,Categories!$C$5:$C$100,"Income")=1),AND(B25="Expense",D25<>"",E25="",F25<>"",COUNTIF(Accounts!$A$5:$A$50,D25)=1,COUNTIFS(Categories!$A$5:$A$100,F25,Categories!$C$5:$C$100,"Expense")=1),AND(B25="Refund",D25="",E25<>"",F25<>"",COUNTIF(Accounts!$A$5:$A$50,E25)=1,COUNTIFS(Categories!$A$5:$A$100,F25,Categories!$C$5:$C$100,"Expense")=1),AND(B25="Transfer",D25<>"",E25<>"",D25<>E25,F25="",COUNTIF(Accounts!$A$5:$A$50,D25)=1,COUNTIF(Accounts!$A$5:$A$50,E25)=1),AND(B25="Allocation",F25="Savings & Investment",OR(AND(D25<>"",E25="",COUNTIFS(Accounts!$A$5:$A$50,D25,Accounts!$D$5:$D$50,"Asset")=1),AND(D25="",E25<>"",COUNTIFS(Accounts!$A$5:$A$50,E25,Accounts!$D$5:$D$50,"Asset")=1))),AND(B25="Adjustment",F25="",OR(AND(D25<>"",E25="",COUNTIF(Accounts!$A$5:$A$50,D25)=1),AND(D25="",E25<>"",COUNTIF(Accounts!$A$5:$A$50,E25)=1)))),"OK","CHECK: Type / account / category combination")))
I26: =IF(COUNTA(A26:H26)=0,"",IF(OR(A26="",B26="",C26="",C26<=0),"CHECK: Date, Type and positive Amount required",IF(OR(AND(B26="Income",D26="",E26<>"",F26<>"",COUNTIFS(Accounts!$A$5:$A$50,E26,Accounts!$D$5:$D$50,"Asset")=1,COUNTIFS(Categories!$A$5:$A$100,F26,Categories!$C$5:$C$100,"Income")=1),AND(B26="Expense",D26<>"",E26="",F26<>"",COUNTIF(Accounts!$A$5:$A$50,D26)=1,COUNTIFS(Categories!$A$5:$A$100,F26,Categories!$C$5:$C$100,"Expense")=1),AND(B26="Refund",D26="",E26<>"",F26<>"",COUNTIF(Accounts!$A$5:$A$50,E26)=1,COUNTIFS(Categories!$A$5:$A$100,F26,Categories!$C$5:$C$100,"Expense")=1),AND(B26="Transfer",D26<>"",E26<>"",D26<>E26,F26="",COUNTIF(Accounts!$A$5:$A$50,D26)=1,COUNTIF(Accounts!$A$5:$A$50,E26)=1),AND(B26="Allocation",F26="Savings & Investment",OR(AND(D26<>"",E26="",COUNTIFS(Accounts!$A$5:$A$50,D26,Accounts!$D$5:$D$50,"Asset")=1),AND(D26="",E26<>"",COUNTIFS(Accounts!$A$5:$A$50,E26,Accounts!$D$5:$D$50,"Asset")=1))),AND(B26="Adjustment",F26="",OR(AND(D26<>"",E26="",COUNTIF(Accounts!$A$5:$A$50,D26)=1),AND(D26="",E26<>"",COUNTIF(Accounts!$A$5:$A$50,E26)=1)))),"OK","CHECK: Type / account / category combination")))
I27: =IF(COUNTA(A27:H27)=0,"",IF(OR(A27="",B27="",C27="",C27<=0),"CHECK: Date, Type and positive Amount required",IF(OR(AND(B27="Income",D27="",E27<>"",F27<>"",COUNTIFS(Accounts!$A$5:$A$50,E27,Accounts!$D$5:$D$50,"Asset")=1,COUNTIFS(Categories!$A$5:$A$100,F27,Categories!$C$5:$C$100,"Income")=1),AND(B27="Expense",D27<>"",E27="",F27<>"",COUNTIF(Accounts!$A$5:$A$50,D27)=1,COUNTIFS(Categories!$A$5:$A$100,F27,Categories!$C$5:$C$100,"Expense")=1),AND(B27="Refund",D27="",E27<>"",F27<>"",COUNTIF(Accounts!$A$5:$A$50,E27)=1,COUNTIFS(Categories!$A$5:$A$100,F27,Categories!$C$5:$C$100,"Expense")=1),AND(B27="Transfer",D27<>"",E27<>"",D27<>E27,F27="",COUNTIF(Accounts!$A$5:$A$50,D27)=1,COUNTIF(Accounts!$A$5:$A$50,E27)=1),AND(B27="Allocation",F27="Savings & Investment",OR(AND(D27<>"",E27="",COUNTIFS(Accounts!$A$5:$A$50,D27,Accounts!$D$5:$D$50,"Asset")=1),AND(D27="",E27<>"",COUNTIFS(Accounts!$A$5:$A$50,E27,Accounts!$D$5:$D$50,"Asset")=1))),AND(B27="Adjustment",F27="",OR(AND(D27<>"",E27="",COUNTIF(Accounts!$A$5:$A$50,D27)=1),AND(D27="",E27<>"",COUNTIF(Accounts!$A$5:$A$50,E27)=1)))),"OK","CHECK: Type / account / category combination")))
I28: =IF(COUNTA(A28:H28)=0,"",IF(OR(A28="",B28="",C28="",C28<=0),"CHECK: Date, Type and positive Amount required",IF(OR(AND(B28="Income",D28="",E28<>"",F28<>"",COUNTIFS(Accounts!$A$5:$A$50,E28,Accounts!$D$5:$D$50,"Asset")=1,COUNTIFS(Categories!$A$5:$A$100,F28,Categories!$C$5:$C$100,"Income")=1),AND(B28="Expense",D28<>"",E28="",F28<>"",COUNTIF(Accounts!$A$5:$A$50,D28)=1,COUNTIFS(Categories!$A$5:$A$100,F28,Categories!$C$5:$C$100,"Expense")=1),AND(B28="Refund",D28="",E28<>"",F28<>"",COUNTIF(Accounts!$A$5:$A$50,E28)=1,COUNTIFS(Categories!$A$5:$A$100,F28,Categories!$C$5:$C$100,"Expense")=1),AND(B28="Transfer",D28<>"",E28<>"",D28<>E28,F28="",COUNTIF(Accounts!$A$5:$A$50,D28)=1,COUNTIF(Accounts!$A$5:$A$50,E28)=1),AND(B28="Allocation",F28="Savings & Investment",OR(AND(D28<>"",E28="",COUNTIFS(Accounts!$A$5:$A$50,D28,Accounts!$D$5:$D$50,"Asset")=1),AND(D28="",E28<>"",COUNTIFS(Accounts!$A$5:$A$50,E28,Accounts!$D$5:$D$50,"Asset")=1))),AND(B28="Adjustment",F28="",OR(AND(D28<>"",E28="",COUNTIF(Accounts!$A$5:$A$50,D28)=1),AND(D28="",E28<>"",COUNTIF(Accounts!$A$5:$A$50,E28)=1)))),"OK","CHECK: Type / account / category combination")))
... I499: =IF(COUNTA(A499:H499)=0,"",IF(OR(A499="",B499="",C499="",C499<=0),"CHECK: Date, Type and positive Amount required",IF(OR(AND(B499="Income",D499="",E499<>"",F499<>"",COUNTIFS(Accounts!$A$5:$A$50,E499,Accounts!$D$5:$D$50,"Asset")=1,COUNTIFS(Categories!$A$5:$A$100,F499,Categories!$C$5:$C$100,"Income")=1),AND(B499="Expense",D499<>"",E499="",F499<>"",COUNTIF(Accounts!$A$5:$A$50,D499)=1,COUNTIFS(Categories!$A$5:$A$100,F499,Categories!$C$5:$C$100,"Expense")=1),AND(B499="Refund",D499="",E499<>"",F499<>"",COUNTIF(Accounts!$A$5:$A$50,E499)=1,COUNTIFS(Categories!$A$5:$A$100,F499,Categories!$C$5:$C$100,"Expense")=1),AND(B499="Transfer",D499<>"",E499<>"",D499<>E499,F499="",COUNTIF(Accounts!$A$5:$A$50,D499)=1,COUNTIF(Accounts!$A$5:$A$50,E499)=1),AND(B499="Allocation",F499="Savings & Investment",OR(AND(D499<>"",E499="",COUNTIFS(Accounts!$A$5:$A$50,D499,Accounts!$D$5:$D$50,"Asset")=1),AND(D499="",E499<>"",COUNTIFS(Accounts!$A$5:$A$50,E499,Accounts!$D$5:$D$50,"Asset")=1))),AND(B499="Adjustment",F499="",OR(AND(D499<>"",E499="",COUNTIF(Accounts!$A$5:$A$50,D499)=1),AND(D499="",E499<>"",COUNTIF(Accounts!$A$5:$A$50,E499)=1)))),"OK","CHECK: Type / account / category combination")))

Sheet Accounts
A1: Accounts | B1: Accounts | C1: Accounts | D1: Accounts | E1: Accounts | F1: Accounts | G1: Accounts | H1: Accounts | I1: Accounts
A2: Synthetic demo accounts. Opening balances are at the start of 01/09/2026. | B2: Enter opening balances before the first tracked transaction. Liability balances are positive debt owed. | C2: Enter opening balances before the first tracked transaction. Liability balances are positive debt owed. | D2: Enter opening balances before the first tracked transaction. Liability balances are positive debt owed. | E2: Enter opening balances before the first tracked transaction. Liability balances are positive debt owed. | F2: Enter opening balances before the first tracked transaction. Liability balances are positive debt owed. | G2: Enter opening balances before the first tracked transaction. Liability balances are positive debt owed. | H2: Enter opening balances before the first tracked transaction. Liability balances are positive debt owed. | I2: Enter opening balances before the first tracked transaction. Liability balances are positive debt owed.
A4: Account Name | B4: Institution | C4: Account Type | D4: Account Class | E4: Opening Balance | F4: Opening Date | G4: Credit Limit | H4: Active | I4: Current Balance
A5: Bank | B5: Demo Bank | C5: Bank | D5: Asset | E5: 1000000 | F5: 46266 | H5: Yes | I5: =IF(COUNT($E5)=0,"",$E5+IF($D5="Asset",SUMIFS(Transactions!$C$5:$C$2001,Transactions!$I$5:$I$2001,"OK",Transactions!$I$5:$I$2001,"OK",Transactions!$I$5:$I$2001,"OK",Transactions!$I$5:$I$2001,"OK",Transactions!$I$5:$I$2001,"OK",Transactions!$E$5:$E$2001,$A5,Transactions!$A$5:$A$2001,">="&$F5)-SUMIFS(Transactions!$C$5:$C$2001,Transactions!$I$5:$I$2001,"OK",Transactions!$I$5:$I$2001,"OK",Transactions!$I$5:$I$2001,"OK",Transactions!$I$5:$I$2001,"OK",Transactions!$I$5:$I$2001,"OK",Transactions!$D$5:$D$2001,$A5,Transactions!$A$5:$A$2001,">="&$F5),SUMIFS(Transactions!$C$5:$C$2001,Transactions!$I$5:$I$2001,"OK",Transactions!$I$5:$I$2001,"OK",Transactions!$I$5:$I$2001,"OK",Transactions!$I$5:$I$2001,"OK",Transactions!$I$5:$I$2001,"OK",Transactions!$D$5:$D$2001,$A5,Transactions!$A$5:$A$2001,">="&$F5)-SUMIFS(Transactions!$C$5:$C$2001,Transactions!$I$5:$I$2001,"OK",Transactions!$I$5:$I$2001,"OK",Transactions!$I$5:$I$2001,"OK",Transactions!$I$5:$I$2001,"OK",Transactions!$I$5:$I$2001,"OK",Transactions!$E$5:$E$2001,$A5,Transactions!$A$5:$A$2001,">="&$F5))) -> 3130000
A6: Wallet | B6: Demo Wallet | C6: E-wallet | D6: Asset | E6: 100000 | F6: 46266 | H6: Yes | I6: =IF(COUNT($E6)=0,"",$E6+IF($D6="Asset",SUMIFS(Transactions!$C$5:$C$2001,Transactions!$I$5:$I$2001,"OK",Transactions!$I$5:$I$2001,"OK",Transactions!$I$5:$I$2001,"OK",Transactions!$I$5:$I$2001,"OK",Transactions!$I$5:$I$2001,"OK",Transactions!$E$5:$E$2001,$A6,Transactions!$A$5:$A$2001,">="&$F6)-SUMIFS(Transactions!$C$5:$C$2001,Transactions!$I$5:$I$2001,"OK",Transactions!$I$5:$I$2001,"OK",Transactions!$I$5:$I$2001,"OK",Transactions!$I$5:$I$2001,"OK",Transactions!$I$5:$I$2001,"OK",Transactions!$D$5:$D$2001,$A6,Transactions!$A$5:$A$2001,">="&$F6),SUMIFS(Transactions!$C$5:$C$2001,Transactions!$I$5:$I$2001,"OK",Transactions!$I$5:$I$2001,"OK",Transactions!$I$5:$I$2001,"OK",Transactions!$I$5:$I$2001,"OK",Transactions!$I$5:$I$2001,"OK",Transactions!$D$5:$D$2001,$A6,Transactions!$A$5:$A$2001,">="&$F6)-SUMIFS(Transactions!$C$5:$C$2001,Transactions!$I$5:$I$2001,"OK",Transactions!$I$5:$I$2001,"OK",Transactions!$I$5:$I$2001,"OK",Transactions!$I$5:$I$2001,"OK",Transactions!$I$5:$I$2001,"OK",Transactions!$E$5:$E$2001,$A6,Transactions!$A$5:$A$2001,">="&$F6))) -> 155000
A7: Credit Card | B7: Demo Bank | C7: Credit Card | D7: Liability | E7: 0 | F7: 46266 | G7: 2000000 | H7: Yes | I7: =IF(COUNT($E7)=0,"",$E7+IF($D7="Asset",SUMIFS(Transactions!$C$5:$C$2001,Transactions!$I$5:$I$2001,"OK",Transactions!$I$5:$I$2001,"OK",Transactions!$I$5:$I$2001,"OK",Transactions!$I$5:$I$2001,"OK",Transactions!$I$5:$I$2001,"OK",Transactions!$E$5:$E$2001,$A7,Transactions!$A$5:$A$2001,">="&$F7)-SUMIFS(Transactions!$C$5:$C$2001,Transactions!$I$5:$I$2001,"OK",Transactions!$I$5:$I$2001,"OK",Transactions!$I$5:$I$2001,"OK",Transactions!$I$5:$I$2001,"OK",Transactions!$I$5:$I$2001,"OK",Transactions!$D$5:$D$2001,$A7,Transactions!$A$5:$A$2001,">="&$F7),SUMIFS(Transactions!$C$5:$C$2001,Transactions!$I$5:$I$2001,"OK",Transactions!$I$5:$I$2001,"OK",Transactions!$I$5:$I$2001,"OK",Transactions!$I$5:$I$2001,"OK",Transactions!$I$5:$I$2001,"OK",Transactions!$D$5:$D$2001,$A7,Transactions!$A$5:$A$2001,">="&$F7)-SUMIFS(Transactions!$C$5:$C$2001,Transactions!$I$5:$I$2001,"OK",Transactions!$I$5:$I$2001,"OK",Transactions!$I$5:$I$2001,"OK",Transactions!$I$5:$I$2001,"OK",Transactions!$I$5:$I$2001,"OK",Transactions!$E$5:$E$2001,$A7,Transactions!$A$5:$A$2001,">="&$F7))) -> 120000
I8: =IF(COUNT($E8)=0,"",$E8+IF($D8="Asset",SUMIFS(Transactions!$C$5:$C$2001,Transactions!$I$5:$I$2001,"OK",Transactions!$I$5:$I$2001,"OK",Transactions!$I$5:$I$2001,"OK",Transactions!$I$5:$I$2001,"OK",Transactions!$I$5:$I$2001,"OK",Transactions!$E$5:$E$2001,$A8,Transactions!$A$5:$A$2001,">="&$F8)-SUMIFS(Transactions!$C$5:$C$2001,Transactions!$I$5:$I$2001,"OK",Transactions!$I$5:$I$2001,"OK",Transactions!$I$5:$I$2001,"OK",Transactions!$I$5:$I$2001,"OK",Transactions!$I$5:$I$2001,"OK",Transactions!$D$5:$D$2001,$A8,Transactions!$A$5:$A$2001,">="&$F8),SUMIFS(Transactions!$C$5:$C$2001,Transactions!$I$5:$I$2001,"OK",Transactions!$I$5:$I$2001,"OK",Transactions!$I$5:$I$2001,"OK",Transactions!$I$5:$I$2001,"OK",Transactions!$I$5:$I$2001,"OK",Transactions!$D$5:$D$2001,$A8,Transactions!$A$5:$A$2001,">="&$F8)-SUMIFS(Transactions!$C$5:$C$2001,Transactions!$I$5:$I$2001,"OK",Transactions!$I$5:$I$2001,"OK",Transactions!$I$5:$I$2001,"OK",Transactions!$I$5:$I$2001,"OK",Transactions!$I$5:$I$2001,"OK",Transactions!$E$5:$E$2001,$A8,Transactions!$A$5:$A$2001,">="&$F8)))
I9: =IF(COUNT($E9)=0,"",$E9+IF($D9="Asset",SUMIFS(Transactions!$C$5:$C$2001,Transactions!$I$5:$I$2001,"OK",Transactions!$I$5:$I$2001,"OK",Transactions!$I$5:$I$2001,"OK",Transactions!$I$5:$I$2001,"OK",Transactions!$I$5:$I$2001,"OK",Transactions!$E$5:$E$2001,$A9,Transactions!$A$5:$A$2001,">="&$F9)-SUMIFS(Transactions!$C$5:$C$2001,Transactions!$I$5:$I$2001,"OK",Transactions!$I$5:$I$2001,"OK",Transactions!$I$5:$I$2001,"OK",Transactions!$I$5:$I$2001,"OK",Transactions!$I$5:$I$2001,"OK",Transactions!$D$5:$D$2001,$A9,Transactions!$A$5:$A$2001,">="&$F9),SUMIFS(Transactions!$C$5:$C$2001,Transactions!$I$5:$I$2001,"OK",Transactions!$I$5:$I$2001,"OK",Transactions!$I$5:$I$2001,"OK",Transactions!$I$5:$I$2001,"OK",Transactions!$I$5:$I$2001,"OK",Transactions!$D$5:$D$2001,$A9,Transactions!$A$5:$A$2001,">="&$F9)-SUMIFS(Transactions!$C$5:$C$2001,Transactions!$I$5:$I$2001,"OK",Transactions!$I$5:$I$2001,"OK",Transactions!$I$5:$I$2001,"OK",Transactions!$I$5:$I$2001,"OK",Transactions!$I$5:$I$2001,"OK",Transactions!$E$5:$E$2001,$A9,Transactions!$A$5:$A$2001,">="&$F9)))

Sheet Categories
A1: Categories | B1: Categories | C1: Categories | D1: Categories | E1: Categories | F1: Categories
A2: These classifications are defaults. Adjust them after real use shows what is useful. | B2: These classifications are defaults. Adjust them after real use shows what is useful. | C2: These classifications are defaults. Adjust them after real use shows what is useful. | D2: These classifications are defaults. Adjust them after real use shows what is useful. | E2: These classifications are defaults. Adjust them after real use shows what is useful. | F2: These classifications are defaults. Adjust them after real use shows what is useful.
A4: Category Name | B4: Category Group | C4: Allowed Type | D4: Need / Want | E4: Fixed / Variable | F4: Active
A5: Salary | B5: Income | C5: Income | D5: N/A | E5: N/A | F5: Yes
A6: Other Income | B6: Income | C6: Income | D6: N/A | E6: N/A | F6: Yes
A7: Groceries & Essentials | B7: Food | C7: Expense | D7: Need | E7: Variable | F7: Yes
A8: Eating Out & Drinks | B8: Food | C8: Expense | D8: Want | E8: Variable | F8: Yes
A9: Transport | B9: Transport | C9: Expense | D9: Need | E9: Variable | F9: Yes
A10: Housing | B10: Housing | C10: Expense | D10: Need | E10: Fixed | F10: Yes
A11: Utilities & Mobile | B11: Housing | C11: Expense | D11: Need | E11: Variable | F11: Yes
A12: Education & Career | B12: Education | C12: Expense | D12: Need | E12: Variable | F12: Yes
A13: Health | B13: Health | C13: Expense | D13: Need | E13: Variable | F13: Yes
... A20: Savings & Investment | B20: Future | C20: Allocation | D20: N/A | E20: N/A | F20: Yes

Sheet Monthly Plan
A1: Monthly Plan | B1: Monthly Plan | C1: Monthly Plan
A2: Allocation target is separate from expense budgets. Add expense rows only when useful. | B2: Allocation target is separate from expense budgets. Add expense rows only when useful. | C2: Allocation target is separate from expense budgets. Add expense rows only when useful.
A4: Month | B4: Category | C4: Planned Amount
A5: 46266 | B5: Groceries & Essentials | C5: 600000
A6: 46266 | B6: Shopping | C6: 250000
A7: 46266 | B7: Fees & Interest | C7: 50000
A8: 46266 | B8: Savings & Investment | C8: 500000

Sheet Summary
A1: Monthly Summary | B1: Monthly Summary | C1: Monthly Summary | D1: Monthly Summary | E1: Monthly Summary | F1: Monthly Summary | G1: Monthly Summary | H1: Monthly Summary | I1: Monthly Summary | J1: Monthly Summary | K1: Monthly Summary | L1: Monthly Summary
A2: Live Excel summary — no Power Query refresh required | B2: Live Excel summary — no Power Query refresh required | C2: Live Excel summary — no Power Query refresh required | D2: Live Excel summary — no Power Query refresh required | E2: Live Excel summary — no Power Query refresh required | F2: Live Excel summary — no Power Query refresh required | G2: Live Excel summary — no Power Query refresh required | H2: Live Excel summary — no Power Query refresh required | I2: Selected Month | J2: Selected Month | K2: Selected Month | L2: 46266
A4: Total Income | B4: Total Income | C4: Total Income | D4: Net Expense | E4: Net Expense | F4: Net Expense | G4: Monthly Surplus | H4: Monthly Surplus | I4: Monthly Surplus | J4: Allocation Contribution | K4: Allocation Contribution | L4: Allocation Contribution
A5: =SUMIFS(Transactions!$C$5:$C$2001,Transactions!$I$5:$I$2001,"OK",Transactions!$B$5:$B$2001,"Income",Transactions!$A$5:$A$2001,">="&$L$2,Transactions!$A$5:$A$2001,"<"&EDATE($L$2,1)) -> 3000000 | D5: =SUMIFS(Transactions!$C$5:$C$2001,Transactions!$I$5:$I$2001,"OK",Transactions!$B$5:$B$2001,"Expense",Transactions!$A$5:$A$2001,">="&$L$2,Transactions!$A$5:$A$2001,"<"&EDATE($L$2,1))-SUMIFS(Transactions!$C$5:$C$2001,Transactions!$I$5:$I$2001,"OK",Transactions!$B$5:$B$2001,"Refund",Transactions!$A$5:$A$2001,">="&$L$2,Transactions!$A$5:$A$2001,"<"&EDATE($L$2,1)) -> 640000 | G5: =SUMIFS(Transactions!$C$5:$C$2001,Transactions!$I$5:$I$2001,"OK",Transactions!$B$5:$B$2001,"Income",Transactions!$A$5:$A$2001,">="&$L$2,Transactions!$A$5:$A$2001,"<"&EDATE($L$2,1))-(SUMIFS(Transactions!$C$5:$C$2001,Transactions!$I$5:$I$2001,"OK",Transactions!$B$5:$B$2001,"Expense",Transactions!$A$5:$A$2001,">="&$L$2,Transactions!$A$5:$A$2001,"<"&EDATE($L$2,1))-SUMIFS(Transactions!$C$5:$C$2001,Transactions!$I$5:$I$2001,"OK",Transactions!$B$5:$B$2001,"Refund",Transactions!$A$5:$A$2001,">="&$L$2,Transactions!$A$5:$A$2001,"<"&EDATE($L$2,1))) -> 2360000 | J5: =SUMIFS(Transactions!$C$5:$C$2001,Transactions!$I$5:$I$2001,"OK",Transactions!$B$5:$B$2001,"Allocation",Transactions!$D$5:$D$2001,"<>",Transactions!$A$5:$A$2001,">="&$L$2,Transactions!$A$5:$A$2001,"<"&EDATE($L$2,1)) -> 400000
A6: Money earned during the selected month | B6: Money earned during the selected month | C6: Money earned during the selected month | D6: Gross expense less refunds | E6: Gross expense less refunds | F6: Gross expense less refunds | G6: Income less Net Expense; before Allocation | H6: Income less Net Expense; before Allocation | I6: Income less Net Expense; before Allocation | J6: Gross outbound Savings & Investment | K6: Gross outbound Savings & Investment | L6: Gross outbound Savings & Investment
A8: Tracked Liquid Assets | B8: Tracked Liquid Assets | C8: Tracked Liquid Assets | D8: Outstanding Debt | E8: Outstanding Debt | F8: Outstanding Debt | G8: Tracked Net Position | H8: Tracked Net Position | I8: Tracked Net Position | J8: Allocation Progress | K8: Allocation Progress | L8: Allocation Progress
A9: =SUMIFS(Accounts!$I$5:$I$50,Accounts!$D$5:$D$50,"Asset") -> 3285000 | D9: =SUMIFS(Accounts!$I$5:$I$50,Accounts!$D$5:$D$50,"Liability") -> 120000 | G9: =A9-D9 -> 3165000 | J9: =IFERROR(J5/SUMIFS('Monthly Plan'!$C$5:$C$199,'Monthly Plan'!$A$5:$A$199,$L$2,'Monthly Plan'!$B$5:$B$199,"Savings & Investment"),0) -> 0.8
A10: Active and inactive tracked asset balances | B10: Active and inactive tracked asset balances | C10: Active and inactive tracked asset balances | D10: Natural credit-account balances | E10: Credit Card + Pay-later natural balances | F10: Credit Card + Pay-later natural balances | G10: Tracked assets less tracked debt | H10: Tracked assets less tracked debt | I10: Tracked assets less tracked debt | J10: Target is separate from Expense Budget | K10: Target is separate from Expense Budget | L10: Target is separate from Expense Budget
A12: Account Balances | B12: Account Balances | C12: Account Balances | D12: Account Balances | E12: Account Balances | G12: Expense vs Budget | H12: Expense vs Budget | I12: Expense vs Budget | J12: Expense vs Budget
A13: Account | B13: Class | C13: Current Balance | D13: Credit Limit | E13: Available Limit | G13: Category | H13: Actual | I13: Budget | J13: Variance
A14: =IF(Accounts!A5="","",Accounts!A5) -> Bank | B14: =IF(Accounts!D5="","",Accounts!D5) -> Asset | C14: =IF(COUNT(Accounts!E5)=0,"",Accounts!I5) -> 3130000 | D14: =IF(COUNT(Accounts!G5)=0,"",Accounts!G5) | E14: =IF(OR(B14<>"Liability",D14="",C14=""),"",D14-C14) | G14: =Categories!A7 -> Groceries & Essentials | H14: =SUMIFS(Transactions!$C$5:$C$2001,Transactions!$I$5:$I$2001,"OK",Transactions!$B$5:$B$2001,"Expense",Transactions!$F$5:$F$2001,$G14,Transactions!$A$5:$A$2001,">="&$L$2,Transactions!$A$5:$A$2001,"<"&EDATE($L$2,1))-SUMIFS(Transactions!$C$5:$C$2001,Transactions!$I$5:$I$2001,"OK",Transactions!$B$5:$B$2001,"Refund",Transactions!$F$5:$F$2001,$G14,Transactions!$A$5:$A$2001,">="&$L$2,Transactions!$A$5:$A$2001,"<"&EDATE($L$2,1)) -> 450000 | I14: =SUMIFS('Monthly Plan'!$C$5:$C$199,'Monthly Plan'!$A$5:$A$199,$L$2,'Monthly Plan'!$B$5:$B$199,$G14) -> 600000 | J14: =H14-I14 -> -150000
A15: =IF(Accounts!A6="","",Accounts!A6) -> Wallet | B15: =IF(Accounts!D6="","",Accounts!D6) -> Asset | C15: =IF(COUNT(Accounts!E6)=0,"",Accounts!I6) -> 155000 | D15: =IF(COUNT(Accounts!G6)=0,"",Accounts!G6) | E15: =IF(OR(B15<>"Liability",D15="",C15=""),"",D15-C15) | G15: =Categories!A8 -> Eating Out & Drinks | H15: =SUMIFS(Transactions!$C$5:$C$2001,Transactions!$I$5:$I$2001,"OK",Transactions!$B$5:$B$2001,"Expense",Transactions!$F$5:$F$2001,$G15,Transactions!$A$5:$A$2001,">="&$L$2,Transactions!$A$5:$A$2001,"<"&EDATE($L$2,1))-SUMIFS(Transactions!$C$5:$C$2001,Transactions!$I$5:$I$2001,"OK",Transactions!$B$5:$B$2001,"Refund",Transactions!$F$5:$F$2001,$G15,Transactions!$A$5:$A$2001,">="&$L$2,Transactions!$A$5:$A$2001,"<"&EDATE($L$2,1)) -> 0 | I15: =SUMIFS('Monthly Plan'!$C$5:$C$199,'Monthly Plan'!$A$5:$A$199,$L$2,'Monthly Plan'!$B$5:$B$199,$G15) -> 0 | J15: =H15-I15 -> 0
A16: =IF(Accounts!A7="","",Accounts!A7) -> Credit Card | B16: =IF(Accounts!D7="","",Accounts!D7) -> Liability | C16: =IF(COUNT(Accounts!E7)=0,"",Accounts!I7) -> 120000 | D16: =IF(COUNT(Accounts!G7)=0,"",Accounts!G7) -> 2000000 | E16: =IF(OR(B16<>"Liability",D16="",C16=""),"",D16-C16) -> 1880000 | G16: =Categories!A9 -> Transport | H16: =SUMIFS(Transactions!$C$5:$C$2001,Transactions!$I$5:$I$2001,"OK",Transactions!$B$5:$B$2001,"Expense",Transactions!$F$5:$F$2001,$G16,Transactions!$A$5:$A$2001,">="&$L$2,Transactions!$A$5:$A$2001,"<"&EDATE($L$2,1))-SUMIFS(Transactions!$C$5:$C$2001,Transactions!$I$5:$I$2001,"OK",Transactions!$B$5:$B$2001,"Refund",Transactions!$F$5:$F$2001,$G16,Transactions!$A$5:$A$2001,">="&$L$2,Transactions!$A$5:$A$2001,"<"&EDATE($L$2,1)) -> 0 | I16: =SUMIFS('Monthly Plan'!$C$5:$C$199,'Monthly Plan'!$A$5:$A$199,$L$2,'Monthly Plan'!$B$5:$B$199,$G16) -> 0 | J16: =H16-I16 -> 0
A17: =IF(Accounts!A8="","",Accounts!A8) | B17: =IF(Accounts!D8="","",Accounts!D8) | C17: =IF(COUNT(Accounts!E8)=0,"",Accounts!I8) | D17: =IF(COUNT(Accounts!G8)=0,"",Accounts!G8) | E17: =IF(OR(B17<>"Liability",D17="",C17=""),"",D17-C17) | G17: =Categories!A10 -> Housing | H17: =SUMIFS(Transactions!$C$5:$C$2001,Transactions!$I$5:$I$2001,"OK",Transactions!$B$5:$B$2001,"Expense",Transactions!$F$5:$F$2001,$G17,Transactions!$A$5:$A$2001,">="&$L$2,Transactions!$A$5:$A$2001,"<"&EDATE($L$2,1))-SUMIFS(Transactions!$C$5:$C$2001,Transactions!$I$5:$I$2001,"OK",Transactions!$B$5:$B$2001,"Refund",Transactions!$F$5:$F$2001,$G17,Transactions!$A$5:$A$2001,">="&$L$2,Transactions!$A$5:$A$2001,"<"&EDATE($L$2,1)) -> 0 | I17: =SUMIFS('Monthly Plan'!$C$5:$C$199,'Monthly Plan'!$A$5:$A$199,$L$2,'Monthly Plan'!$B$5:$B$199,$G17) -> 0 | J17: =H17-I17 -> 0
A18: =IF(Accounts!A9="","",Accounts!A9) | B18: =IF(Accounts!D9="","",Accounts!D9) | C18: =IF(COUNT(Accounts!E9)=0,"",Accounts!I9) | D18: =IF(COUNT(Accounts!G9)=0,"",Accounts!G9) | E18: =IF(OR(B18<>"Liability",D18="",C18=""),"",D18-C18) | G18: =Categories!A11 -> Utilities & Mobile | H18: =SUMIFS(Transactions!$C$5:$C$2001,Transactions!$I$5:$I$2001,"OK",Transactions!$B$5:$B$2001,"Expense",Transactions!$F$5:$F$2001,$G18,Transactions!$A$5:$A$2001,">="&$L$2,Transactions!$A$5:$A$2001,"<"&EDATE($L$2,1))-SUMIFS(Transactions!$C$5:$C$2001,Transactions!$I$5:$I$2001,"OK",Transactions!$B$5:$B$2001,"Refund",Transactions!$F$5:$F$2001,$G18,Transactions!$A$5:$A$2001,">="&$L$2,Transactions!$A$5:$A$2001,"<"&EDATE($L$2,1)) -> 0 | I18: =SUMIFS('Monthly Plan'!$C$5:$C$199,'Monthly Plan'!$A$5:$A$199,$L$2,'Monthly Plan'!$B$5:$B$199,$G18) -> 0 | J18: =H18-I18 -> 0
G19: =Categories!A12 -> Education & Career | H19: =SUMIFS(Transactions!$C$5:$C$2001,Transactions!$I$5:$I$2001,"OK",Transactions!$B$5:$B$2001,"Expense",Transactions!$F$5:$F$2001,$G19,Transactions!$A$5:$A$2001,">="&$L$2,Transactions!$A$5:$A$2001,"<"&EDATE($L$2,1))-SUMIFS(Transactions!$C$5:$C$2001,Transactions!$I$5:$I$2001,"OK",Transactions!$B$5:$B$2001,"Refund",Transactions!$F$5:$F$2001,$G19,Transactions!$A$5:$A$2001,">="&$L$2,Transactions!$A$5:$A$2001,"<"&EDATE($L$2,1)) -> 0 | I19: =SUMIFS('Monthly Plan'!$C$5:$C$199,'Monthly Plan'!$A$5:$A$199,$L$2,'Monthly Plan'!$B$5:$B$199,$G19) -> 0 | J19: =H19-I19 -> 0
G20: =Categories!A13 -> Health | H20: =SUMIFS(Transactions!$C$5:$C$2001,Transactions!$I$5:$I$2001,"OK",Transactions!$B$5:$B$2001,"Expense",Transactions!$F$5:$F$2001,$G20,Transactions!$A$5:$A$2001,">="&$L$2,Transactions!$A$5:$A$2001,"<"&EDATE($L$2,1))-SUMIFS(Transactions!$C$5:$C$2001,Transactions!$I$5:$I$2001,"OK",Transactions!$B$5:$B$2001,"Refund",Transactions!$F$5:$F$2001,$G20,Transactions!$A$5:$A$2001,">="&$L$2,Transactions!$A$5:$A$2001,"<"&EDATE($L$2,1)) -> 0 | I20: =SUMIFS('Monthly Plan'!$C$5:$C$199,'Monthly Plan'!$A$5:$A$199,$L$2,'Monthly Plan'!$B$5:$B$199,$G20) -> 0 | J20: =H20-I20 -> 0
G21: =Categories!A14 -> Shopping | H21: =SUMIFS(Transactions!$C$5:$C$2001,Transactions!$I$5:$I$2001,"OK",Transactions!$B$5:$B$2001,"Expense",Transactions!$F$5:$F$2001,$G21,Transactions!$A$5:$A$2001,">="&$L$2,Transactions!$A$5:$A$2001,"<"&EDATE($L$2,1))-SUMIFS(Transactions!$C$5:$C$2001,Transactions!$I$5:$I$2001,"OK",Transactions!$B$5:$B$2001,"Refund",Transactions!$F$5:$F$2001,$G21,Transactions!$A$5:$A$2001,">="&$L$2,Transactions!$A$5:$A$2001,"<"&EDATE($L$2,1)) -> 180000 | I21: =SUMIFS('Monthly Plan'!$C$5:$C$199,'Monthly Plan'!$A$5:$A$199,$L$2,'Monthly Plan'!$B$5:$B$199,$G21) -> 250000 | J21: =H21-I21 -> -70000
G22: =Categories!A15 -> Entertainment & Social | H22: =SUMIFS(Transactions!$C$5:$C$2001,Transactions!$I$5:$I$2001,"OK",Transactions!$B$5:$B$2001,"Expense",Transactions!$F$5:$F$2001,$G22,Transactions!$A$5:$A$2001,">="&$L$2,Transactions!$A$5:$A$2001,"<"&EDATE($L$2,1))-SUMIFS(Transactions!$C$5:$C$2001,Transactions!$I$5:$I$2001,"OK",Transactions!$B$5:$B$2001,"Refund",Transactions!$F$5:$F$2001,$G22,Transactions!$A$5:$A$2001,">="&$L$2,Transactions!$A$5:$A$2001,"<"&EDATE($L$2,1)) -> 0 | I22: =SUMIFS('Monthly Plan'!$C$5:$C$199,'Monthly Plan'!$A$5:$A$199,$L$2,'Monthly Plan'!$B$5:$B$199,$G22) -> 0 | J22: =H22-I22 -> 0
G23: =Categories!A16 -> Subscriptions | H23: =SUMIFS(Transactions!$C$5:$C$2001,Transactions!$I$5:$I$2001,"OK",Transactions!$B$5:$B$2001,"Expense",Transactions!$F$5:$F$2001,$G23,Transactions!$A$5:$A$2001,">="&$L$2,Transactions!$A$5:$A$2001,"<"&EDATE($L$2,1))-SUMIFS(Transactions!$C$5:$C$2001,Transactions!$I$5:$I$2001,"OK",Transactions!$B$5:$B$2001,"Refund",Transactions!$F$5:$F$2001,$G23,Transactions!$A$5:$A$2001,">="&$L$2,Transactions!$A$5:$A$2001,"<"&EDATE($L$2,1)) -> 0 | I23: =SUMIFS('Monthly Plan'!$C$5:$C$199,'Monthly Plan'!$A$5:$A$199,$L$2,'Monthly Plan'!$B$5:$B$199,$G23) -> 0 | J23: =H23-I23 -> 0
G24: =Categories!A17 -> Family & Gifts | H24: =SUMIFS(Transactions!$C$5:$C$2001,Transactions!$I$5:$I$2001,"OK",Transactions!$B$5:$B$2001,"Expense",Transactions!$F$5:$F$2001,$G24,Transactions!$A$5:$A$2001,">="&$L$2,Transactions!$A$5:$A$2001,"<"&EDATE($L$2,1))-SUMIFS(Transactions!$C$5:$C$2001,Transactions!$I$5:$I$2001,"OK",Transactions!$B$5:$B$2001,"Refund",Transactions!$F$5:$F$2001,$G24,Transactions!$A$5:$A$2001,">="&$L$2,Transactions!$A$5:$A$2001,"<"&EDATE($L$2,1)) -> 0 | I24: =SUMIFS('Monthly Plan'!$C$5:$C$199,'Monthly Plan'!$A$5:$A$199,$L$2,'Monthly Plan'!$B$5:$B$199,$G24) -> 0 | J24: =H24-I24 -> 0
G25: =Categories!A18 -> Fees & Interest | H25: =SUMIFS(Transactions!$C$5:$C$2001,Transactions!$I$5:$I$2001,"OK",Transactions!$B$5:$B$2001,"Expense",Transactions!$F$5:$F$2001,$G25,Transactions!$A$5:$A$2001,">="&$L$2,Transactions!$A$5:$A$2001,"<"&EDATE($L$2,1))-SUMIFS(Transactions!$C$5:$C$2001,Transactions!$I$5:$I$2001,"OK",Transactions!$B$5:$B$2001,"Refund",Transactions!$F$5:$F$2001,$G25,Transactions!$A$5:$A$2001,">="&$L$2,Transactions!$A$5:$A$2001,"<"&EDATE($L$2,1)) -> 10000 | I25: =SUMIFS('Monthly Plan'!$C$5:$C$199,'Monthly Plan'!$A$5:$A$199,$L$2,'Monthly Plan'!$B$5:$B$199,$G25) -> 50000 | J25: =H25-I25 -> -40000
G26: =Categories!A19 -> Other Expense | H26: =SUMIFS(Transactions!$C$5:$C$2001,Transactions!$I$5:$I$2001,"OK",Transactions!$B$5:$B$2001,"Expense",Transactions!$F$5:$F$2001,$G26,Transactions!$A$5:$A$2001,">="&$L$2,Transactions!$A$5:$A$2001,"<"&EDATE($L$2,1))-SUMIFS(Transactions!$C$5:$C$2001,Transactions!$I$5:$I$2001,"OK",Transactions!$B$5:$B$2001,"Refund",Transactions!$F$5:$F$2001,$G26,Transactions!$A$5:$A$2001,">="&$L$2,Transactions!$A$5:$A$2001,"<"&EDATE($L$2,1)) -> 0 | I26: =SUMIFS('Monthly Plan'!$C$5:$C$199,'Monthly Plan'!$A$5:$A$199,$L$2,'Monthly Plan'!$B$5:$B$199,$G26) -> 0 | J26: =H26-I26 -> 0

Sheet _Lists
A1: Active Accounts | B1: Active Categories | C1: Plan Months
A2: =IF(Accounts!$H5="Yes",Accounts!$A5,"") -> Bank | B2: =IF(Categories!$F5="Yes",Categories!$A5,"") -> Salary | C2: 46266
A3: =IF(Accounts!$H6="Yes",Accounts!$A6,"") -> Wallet | B3: =IF(Categories!$F6="Yes",Categories!$A6,"") -> Other Income | C3: 46296
A4: =IF(Accounts!$H7="Yes",Accounts!$A7,"") -> Credit Card | B4: =IF(Categories!$F7="Yes",Categories!$A7,"") -> Groceries & Essentials | C4: 46327
A5: =IF(Accounts!$H8="Yes",Accounts!$A8,"") | B5: =IF(Categories!$F8="Yes",Categories!$A8,"") -> Eating Out & Drinks | C5: 46357
A6: =IF(Accounts!$H9="Yes",Accounts!$A9,"") | B6: =IF(Categories!$F9="Yes",Categories!$A9,"") -> Transport | C6: 46388
A7: =IF(Accounts!$H10="Yes",Accounts!$A10,"") | B7: =IF(Categories!$F10="Yes",Categories!$A10,"") -> Housing | C7: 46419
A8: =IF(Accounts!$H11="Yes",Accounts!$A11,"") | B8: =IF(Categories!$F11="Yes",Categories!$A11,"") -> Utilities & Mobile | C8: 46447
A9: =IF(Accounts!$H12="Yes",Accounts!$A12,"") | B9: =IF(Categories!$F12="Yes",Categories!$A12,"") -> Education & Career | C9: 46478
A10: =IF(Accounts!$H13="Yes",Accounts!$A13,"") | B10: =IF(Categories!$F13="Yes",Categories!$A13,"") -> Health | C10: 46508
A11: =IF(Accounts!$H14="Yes",Accounts!$A14,"") | B11: =IF(Categories!$F14="Yes",Categories!$A14,"") -> Shopping | C11: 46539
A12: =IF(Accounts!$H15="Yes",Accounts!$A15,"") | B12: =IF(Categories!$F15="Yes",Categories!$A15,"") -> Entertainment & Social | C12: 46569
